<?xml version="1.0" encoding="utf-8" ?>
<testsuites>
    <testsuite errors="0" failures="1" hostname="kokoro-gcp-ubuntu-prod-510315420" name="pytest" skipped="0" tests="1" time="0.732" timestamp="2020-01-02T11:25:09.689422">
        <testcase classname="appengine.flexible.datastore.main_test" file="appengine/flexible/datastore/main_test.py" line="17" name="test_index" time="0.320">
            <failure message="KeyError: &apos;user_ip&apos;">
Traceback (most recent call last):
  File &quot;/tmpfs/src/github/python-docs-samples/appengine/flexible/datastore/main_test.py&quot;, line 22, in test_index
    ...
    </failure>
        </testcase>
    </testsuite>
</testsuites>
