<?xml version="1.0" encoding="utf-8"?><testsuites><testsuite errors="1" failures="0" hostname="kokoro-gcp-ubuntu-prod-13339050" name="pytest" skipped="0" tests="1" time="134.531" timestamp="2020-08-11T11:29:15.048360"><testcase classname="memorystore.redis.cloud_run_deployment.e2e_test" name="test_end_to_end" time="134.482"><error message="failed on setup with &quot;subprocess.CalledProcessError: Command &apos;[&apos;gcloud&apos;, &apos;redis&apos;, &apos;instances&apos;, &apos;create&apos;, &apos;test-instance-44d74c74c5&apos;, &apos;--region=us-central1&apos;, &apos;--network&apos;, &apos;test-network-44d74c74c5&apos;, &apos;--project&apos;, &apos;python-docs-samples-tests&apos;]&apos; returned non-zero exit status 1.&quot;">Traceback (most recent call last):
  File &quot;/workspace/memorystore/redis/cloud_run_deployment/e2e_test.py&quot;, line 70, in services
    subprocess.run(
  File &quot;/usr/local/lib/python3.8/subprocess.py&quot;, line 512, in run
    raise CalledProcessError(retcode, process.args,
subprocess.CalledProcessError: Command &apos;[&apos;gcloud&apos;, &apos;redis&apos;, &apos;instances&apos;, &apos;create&apos;, &apos;test-instance-44d74c74c5&apos;, &apos;--region=us-central1&apos;, &apos;--network&apos;, &apos;test-network-44d74c74c5&apos;, &apos;--project&apos;, &apos;python-docs-samples-tests&apos;]&apos; returned non-zero exit status 1.</error></testcase></testsuite></testsuites>